mplus_output/bi-44-SAGE (South Africa)_W1.out
Mplus VERSION 8.1 (Mac)
MUTHEN & MUTHEN
05/27/2020  10:29 PM

INPUT INSTRUCTIONS

  DATA:
  FILE = "bi-44-SAGE (South Africa)_W1.dat";

  VARIABLE:
  NAMES = mplusid UANI UIWR UIWR2 UIWR3 UDIGF UDIGB;
   MISSING=.;
   CATEGORICAL ARE all; idvariable = mplusid;
  ANALYSIS:
  estimator = wlsmv; coverage=0;
  MODEL:
  g by UIWR * ;
   g by UANI * ;
   g by UIWR2 * ;
   g by UIWR3 * ;
   g by UDIGF * ;
   g by UDIGB * ;
   s1 by UIWR * ;
   s1 by UIWR2 * ;
   s1 by UIWR3 * ;
   g @ 1;
   s1 @ 1 ;
   g with s1 @ 0 ;

  OUTPUT:
  standardized; svalues;



INPUT READING TERMINATED NORMALLY




SUMMARY OF ANALYSIS

Number of groups                                                 1
Number of observations                                        4050

Number of dependent variables                                    6
Number of independent variables                                  0
Number of continuous latent variables                            2

Observed dependent variables

  Binary and ordered categorical (ordinal)
   UANI        UIWR        UIWR2       UIWR3       UDIGF       UDIGB

Continuous latent variables
   G           S1

Variables with special functions

  ID variable           MPLUSID

Estimator                                                    WLSMV
Maximum number of iterations                                  1000
Convergence criterion                                    0.500D-04
Maximum number of steepest descent iterations                   20
Maximum number of iterations for H1                           2000
Convergence criterion for H1                             0.100D-03
Parameterization                                             DELTA
Link                                                        PROBIT

Input data file(s)
  bi-44-SAGE (South Africa)_W1.dat

Input data format  FREE


SUMMARY OF DATA

     Number of missing data patterns            11


COVARIANCE COVERAGE OF DATA

Minimum covariance coverage value   0.000


     PROPORTION OF DATA PRESENT


           Covariance Coverage
              UANI          UIWR          UIWR2         UIWR3         UDIGF
              ________      ________      ________      ________      ________
 UANI           0.999
 UIWR           0.995         0.995
 UIWR2          0.994         0.995         0.995
 UIWR3          0.993         0.994         0.994         0.994
 UDIGF          0.999         0.995         0.994         0.994         1.000
 UDIGB          0.968         0.966         0.965         0.964         0.969


           Covariance Coverage
              UDIGB
              ________
 UDIGB          0.969


UNIVARIATE PROPORTIONS AND COUNTS FOR CATEGORICAL VARIABLES

    UANI
      Category 1    0.030          123.000
      Category 2    0.100          406.000
      Category 3    0.350         1415.000
      Category 4    0.338         1366.000
      Category 5    0.124          500.000
      Category 6    0.046          187.000
      Category 7    0.010           41.000
      Category 8    0.001            4.000
      Category 9    0.000            1.000
      Category 10    0.000            1.000
    UIWR
      Category 1    0.014           57.000
      Category 2    0.010           41.000
      Category 3    0.055          220.000
      Category 4    0.091          366.000
      Category 5    0.172          692.000
      Category 6    0.457         1843.000
      Category 7    0.132          534.000
      Category 8    0.054          218.000
      Category 9    0.011           45.000
      Category 10    0.004           15.000
    UIWR2
      Category 1    0.013           51.000
      Category 2    0.006           24.000
      Category 3    0.023           92.000
      Category 4    0.047          190.000
      Category 5    0.093          373.000
      Category 6    0.382         1540.000
      Category 7    0.230          925.000
      Category 8    0.137          553.000
      Category 9    0.050          201.000
      Category 10    0.020           79.000
    UIWR3
      Category 1    0.016           64.000
      Category 2    0.006           26.000
      Category 3    0.019           75.000
      Category 4    0.028          113.000
      Category 5    0.061          246.000
      Category 6    0.281         1133.000
      Category 7    0.209          843.000
      Category 8    0.193          776.000
      Category 9    0.098          396.000
      Category 10    0.088          353.000
    UDIGF
      Category 1    0.031          127.000
      Category 2    0.083          338.000
      Category 3    0.225          911.000
      Category 4    0.272         1102.000
      Category 5    0.197          797.000
      Category 6    0.106          431.000
      Category 7    0.052          212.000
      Category 8    0.032          131.000
    UDIGB
      Category 1    0.117          458.000
      Category 2    0.201          790.000
      Category 3    0.266         1044.000
      Category 4    0.245          962.000
      Category 5    0.094          369.000
      Category 6    0.041          160.000
      Category 7    0.024           95.000
      Category 8    0.011           45.000



THE MODEL ESTIMATION TERMINATED NORMALLY



MODEL FIT INFORMATION

Number of Free Parameters                       59

Chi-Square Test of Model Fit

          Value                            763.667*
          Degrees of Freedom                     6
          P-Value                           0.0000

*   The chi-square value for MLM, MLMV, MLR, ULSMV, WLSM and WLSMV cannot be used
    for chi-square difference testing in the regular way.  MLM, MLR and WLSM
    chi-square difference testing is described on the Mplus website.  MLMV, WLSMV,
    and ULSMV difference testing is done using the DIFFTEST option.

RMSEA (Root Mean Square Error Of Approximation)

          Estimate                           0.177
          90 Percent C.I.                    0.166  0.187
          Probability RMSEA <= .05           0.000

CFI/TLI

          CFI                                0.970
          TLI                                0.924

Chi-Square Test of Model Fit for the Baseline Model

          Value                          25022.578
          Degrees of Freedom                    15
          P-Value                           0.0000

SRMR (Standardized Root Mean Square Residual)

          Value                              0.028

Optimum Function Value for Weighted Least-Squares Estimator

          Value                     0.46729396D-01



MODEL RESULTS

                                                    Two-Tailed
                    Estimate       S.E.  Est./S.E.    P-Value

 G        BY
    UIWR               0.538      0.014     39.042      0.000
    UANI               0.620      0.013     48.822      0.000
    UIWR2              0.590      0.012     47.401      0.000
    UIWR3              0.627      0.012     52.775      0.000
    UDIGF              0.656      0.011     59.616      0.000
    UDIGB              0.737      0.012     61.781      0.000

 S1       BY
    UIWR               0.467      0.014     33.095      0.000
    UIWR2              0.768      0.013     58.980      0.000
    UIWR3              0.495      0.013     38.212      0.000

 G        WITH
    S1                 0.000      0.000    999.000    999.000

 Thresholds
    UANI$1            -1.875      0.039    -47.778      0.000
    UANI$2            -1.123      0.025    -44.979      0.000
    UANI$3            -0.048      0.020     -2.453      0.014
    UANI$4             0.910      0.023     39.587      0.000
    UANI$5             1.573      0.032     49.603      0.000
    UANI$6             2.269      0.055     40.905      0.000
    UANI$7             2.971      0.125     23.716      0.000
    UANI$8             3.294      0.199     16.573      0.000
    UANI$9             3.484      0.268     13.017      0.000
    UIWR$1            -2.193      0.052    -42.454      0.000
    UIWR$2            -1.972      0.042    -46.409      0.000
