mplus_output/uni-01-HRS_CODA_W6.out
Mplus VERSION 8.1 (Mac)
MUTHEN & MUTHEN
04/23/2020  10:55 PM

INPUT INSTRUCTIONS

  DATA:
  FILE = "uni-01-HRS_CODA_W6.dat";

  VARIABLE:
  NAMES = mplusid UDAT UDAY UMON UYER UIWR UDWR USUB UBAK UNM1 UNM2 UNM5 UNM6;
   MISSING=.;
   CATEGORICAL ARE all; idvariable = mplusid;
  ANALYSIS:
  estimator = wlsmv; coverage=0;
  MODEL:
  g by UDAT * ;
   g by UDAY * ;
   g by UMON * ;
   g by UYER * ;
   g by UIWR * ;
   g by UDWR * ;
   g by USUB * ;
   g by UBAK * ;
   g by UNM1 * ;
   g by UNM2 * ;
   g by UNM5 * ;
   g by UNM6 * ;
   g @ 1;

  OUTPUT:
  standardized; svalues;



*** WARNING
  Data set contains cases with missing on all variables.
  These cases were not included in the analysis.
  Number of cases with missing on all variables:  133
   1 WARNING(S) FOUND IN THE INPUT INSTRUCTIONS




SUMMARY OF ANALYSIS

Number of groups                                                 1
Number of observations                                        2187

Number of dependent variables                                   12
Number of independent variables                                  0
Number of continuous latent variables                            1

Observed dependent variables

  Binary and ordered categorical (ordinal)
   UDAT        UDAY        UMON        UYER        UIWR        UDWR
   USUB        UBAK        UNM1        UNM2        UNM5        UNM6

Continuous latent variables
   G

Variables with special functions

  ID variable           MPLUSID

Estimator                                                    WLSMV
Maximum number of iterations                                  1000
Convergence criterion                                    0.500D-04
Maximum number of steepest descent iterations                   20
Maximum number of iterations for H1                           2000
Convergence criterion for H1                             0.100D-03
Parameterization                                             DELTA
Link                                                        PROBIT

Input data file(s)
  uni-01-HRS_CODA_W6.dat

Input data format  FREE


SUMMARY OF DATA

     Number of missing data patterns            41


COVARIANCE COVERAGE OF DATA

Minimum covariance coverage value   0.000


     PROPORTION OF DATA PRESENT


           Covariance Coverage
              UDAT          UDAY          UMON          UYER          UIWR
              ________      ________      ________      ________      ________
 UDAT           0.999
 UDAY           0.999         1.000
 UMON           0.998         0.998         0.998
 UYER           0.999         0.999         0.998         0.999
 UIWR           0.985         0.985         0.984         0.985         0.985
 UDWR           0.911         0.911         0.910         0.911         0.911
 USUB           0.902         0.902         0.902         0.902         0.897
 UBAK           0.990         0.990         0.989         0.990         0.979
 UNM1           0.997         0.998         0.996         0.997         0.985
 UNM2           0.984         0.985         0.984         0.984         0.973
 UNM5           0.993         0.993         0.992         0.993         0.980
 UNM6           0.973         0.973         0.972         0.973         0.961


           Covariance Coverage
              UDWR          USUB          UBAK          UNM1          UNM2
              ________      ________      ________      ________      ________
 UDWR           0.911
 USUB           0.840         0.902
 UBAK           0.907         0.901         0.990
 UNM1           0.911         0.902         0.990         0.998
 UNM2           0.900         0.895         0.978         0.985         0.985
 UNM5           0.907         0.898         0.985         0.992         0.980
 UNM6           0.890         0.887         0.965         0.972         0.963


           Covariance Coverage
              UNM5          UNM6
              ________      ________
 UNM5           0.993
 UNM6           0.972         0.973


UNIVARIATE PROPORTIONS AND COUNTS FOR CATEGORICAL VARIABLES

    UDAT
      Category 1    0.163          356.000
      Category 2    0.837         1829.000
    UDAY
      Category 1    0.019           41.000
      Category 2    0.981         2145.000
    UMON
      Category 1    0.019           41.000
      Category 2    0.981         2142.000
    UYER
      Category 1    0.019           42.000
      Category 2    0.981         2143.000
    UIWR
      Category 1    0.000            1.000
      Category 2    0.008           18.000
      Category 3    0.028           61.000
      Category 4    0.077          167.000
      Category 5    0.155          333.000
      Category 6    0.502         1082.000
      Category 7    0.146          314.000
      Category 8    0.057          122.000
      Category 9    0.020           43.000
      Category 10    0.006           14.000
    UDWR
      Category 1    0.003            5.000
      Category 2    0.041           82.000
      Category 3    0.088          176.000
      Category 4    0.161          320.000
      Category 5    0.220          439.000
      Category 6    0.378          754.000
      Category 7    0.072          144.000
      Category 8    0.022           43.000
      Category 9    0.010           20.000
      Category 10    0.005           10.000
    USUB
      Category 1    0.036           71.000
      Category 2    0.081          159.000
      Category 3    0.089          176.000
      Category 4    0.127          251.000
      Category 5    0.203          400.000
      Category 6    0.464          916.000
    UBAK
      Category 1    0.043           93.000
      Category 2    0.957         2073.000
    UNM1
      Category 1    0.007           16.000
      Category 2    0.993         2166.000
    UNM2
      Category 1    0.058          126.000
      Category 2    0.942         2028.000
    UNM5
      Category 1    0.023           50.000
      Category 2    0.977         2122.000
    UNM6
      Category 1    0.108          230.000
      Category 2    0.892         1898.000


     WARNING:  THE BIVARIATE TABLE OF UNM1 AND UMON HAS AN EMPTY CELL.


THE MODEL ESTIMATION TERMINATED NORMALLY



MODEL FIT INFORMATION

Number of Free Parameters                       44

Chi-Square Test of Model Fit

          Value                            376.871*
          Degrees of Freedom                    54
          P-Value                           0.0000

*   The chi-square value for MLM, MLMV, MLR, ULSMV, WLSM and WLSMV cannot be used
    for chi-square difference testing in the regular way.  MLM, MLR and WLSM
    chi-square difference testing is described on the Mplus website.  MLMV, WLSMV,
    and ULSMV difference testing is done using the DIFFTEST option.

RMSEA (Root Mean Square Error Of Approximation)

          Estimate                           0.052
          90 Percent C.I.                    0.047  0.057
          Probability RMSEA <= .05           0.217

CFI/TLI

          CFI                                0.959
          TLI                                0.950

Chi-Square Test of Model Fit for the Baseline Model

          Value                           8018.030
          Degrees of Freedom                    66
          P-Value                           0.0000

SRMR (Standardized Root Mean Square Residual)

          Value                              0.108

Optimum Function Value for Weighted Least-Squares Estimator

          Value                     0.79465419D-01



MODEL RESULTS

                                                    Two-Tailed
                    Estimate       S.E.  Est./S.E.    P-Value

 G        BY
    UDAT               0.303      0.032      9.373      0.000
    UDAY               0.593      0.062      9.503      0.000
    UMON               0.547      0.067      8.111      0.000
    UYER               0.878      0.049     18.040      0.000
    UIWR               0.860      0.017     50.678      0.000
    UDWR               0.869      0.018     49.116      0.000
